try {
	std::vector<int> v = {1, 2, 3};
	std::cout << v.at(5) << std::endl;
} catch (const std::exception& e) {
	std::cerr << e.what() << std::endl;
}
